<?xml version="1.0" ?>
<robot name="Robotic" xmlns:xacro="http://www.ros.org/wiki/xacro">

<xacro:include filename="$(find Robotic_description)/urdf/materials.xacro" />
<xacro:include filename="$(find Robotic_description)/urdf/Robotic.trans" />
<xacro:include filename="$(find Robotic_description)/urdf/Robotic.gazebo" />
<link name="base_link">
  <inertial>
    <origin xyz="0.0007806396519895978 -0.0007806396451176682 0.04859351552798209" rpy="0 0 0"/>
    <mass value="12.47367775880617"/>
    <inertia ixx="0.118752" iyy="0.118752" izz="0.218412" ixy="0.000272" iyz="-0.000713" ixz="0.000713"/>
  </inertial>
  <visual>
    <origin xyz="0 0 0" rpy="0 0 0"/>
    <geometry>
      <mesh filename="package://Robotic_description/meshes/base_link.stl" scale="0.001 0.001 0.001"/>
    </geometry>
    <material name="silver"/>
  </visual>
  <collision>
    <origin xyz="0 0 0" rpy="0 0 0"/>
    <geometry>
      <mesh filename="package://Robotic_description/meshes/base_link.stl" scale="0.001 0.001 0.001"/>
    </geometry>
  </collision>
</link>

<link name="Component2_1">
  <inertial>
    <origin xyz="-0.017857616220766044 0.054057204262383085 0.06290227912529593" rpy="0 0 0"/>
    <mass value="18.09836147401845"/>
    <inertia ixx="0.177958" iyy="0.101915" izz="0.127406" ixy="0.027164" iyz="-0.067671" ixz="0.022129"/>
  </inertial>
  <visual>
    <origin xyz="-0.0 -0.0 -0.104" rpy="0 0 0"/>
    <geometry>
      <mesh filename="package://Robotic_description/meshes/Component2_1.stl" scale="0.001 0.001 0.001"/>
    </geometry>
    <material name="silver"/>
  </visual>
  <collision>
    <origin xyz="-0.0 -0.0 -0.104" rpy="0 0 0"/>
    <geometry>
      <mesh filename="package://Robotic_description/meshes/Component2_1.stl" scale="0.001 0.001 0.001"/>
    </geometry>
  </collision>
</link>

<link name="Component3_1">
  <inertial>
    <origin xyz="0.056604318197619276 -0.07232932500589419 0.1074091525160209" rpy="0 0 0"/>
    <mass value="6.899829498653834"/>
    <inertia ixx="0.13119" iyy="0.091516" izz="0.047481" ixy="0.011146" iyz="0.058201" ixz="-0.015523"/>
  </inertial>
  <visual>
    <origin xyz="0.039991 -0.144571 -0.244" rpy="0 0 0"/>
    <geometry>
      <mesh filename="package://Robotic_description/meshes/Component3_1.stl" scale="0.001 0.001 0.001"/>
    </geometry>
    <material name="silver"/>
  </visual>
  <collision>
    <origin xyz="0.039991 -0.144571 -0.244" rpy="0 0 0"/>
    <geometry>
      <mesh filename="package://Robotic_description/meshes/Component3_1.stl" scale="0.001 0.001 0.001"/>
    </geometry>
  </collision>
</link>

<link name="Component4_1">
  <inertial>
    <origin xyz="-0.037229257165138384 0.04065002788003971 0.018985873388544516" rpy="0 0 0"/>
    <mass value="9.99270875492589"/>
    <inertia ixx="0.048518" iyy="0.021455" izz="0.043108" ixy="0.00925" iyz="0.012379" ixz="-0.002929"/>
  </inertial>
  <visual>
    <origin xyz="-0.013479 0.048728 -0.530839" rpy="0 0 0"/>
    <geometry>
      <mesh filename="package://Robotic_description/meshes/Component4_1.stl" scale="0.001 0.001 0.001"/>
    </geometry>
    <material name="silver"/>
  </visual>
  <collision>
    <origin xyz="-0.013479 0.048728 -0.530839" rpy="0 0 0"/>
    <geometry>
      <mesh filename="package://Robotic_description/meshes/Component4_1.stl" scale="0.001 0.001 0.001"/>
    </geometry>
  </collision>
</link>

<link name="Component5_1">
  <inertial>
    <origin xyz="-0.023811169806457685 0.086081337946948 -0.04461041482865563" rpy="0 0 0"/>
    <mass value="4.896548707938915"/>
    <inertia ixx="0.015432" iyy="0.007725" izz="0.01393" ixy="0.00265" iyz="0.004658" ixz="-0.00068"/>
  </inertial>
  <visual>
    <origin xyz="0.065803 -0.136774 -0.481281" rpy="0 0 0"/>
    <geometry>
      <mesh filename="package://Robotic_description/meshes/Component5_1.stl" scale="0.001 0.001 0.001"/>
    </geometry>
    <material name="silver"/>
  </visual>
  <collision>
    <origin xyz="0.065803 -0.136774 -0.481281" rpy="0 0 0"/>
    <geometry>
      <mesh filename="package://Robotic_description/meshes/Component5_1.stl" scale="0.001 0.001 0.001"/>
    </geometry>
  </collision>
</link>

<link name="Component6_1">
  <inertial>
    <origin xyz="-0.06333818594644106 0.00042092014078587425 -0.5167934992969501" rpy="0 0 0"/>
    <mass value="2.4502212088594084"/>
    <inertia ixx="0.002207" iyy="0.002455" izz="0.002101" ixy="-0.000158" iyz="-0.000176" ixz="-0.000392"/>
  </inertial>
  <visual>
    <origin xyz="0.002672 -0.290546 -0.970153" rpy="0 0 0"/>
    <geometry>
      <mesh filename="package://Robotic_description/meshes/Component6_1.stl" scale="0.001 0.001 0.001"/>
    </geometry>
    <material name="silver"/>
  </visual>
  <collision>
    <origin xyz="0.002672 -0.290546 -0.970153" rpy="0 0 0"/>
    <geometry>
      <mesh filename="package://Robotic_description/meshes/Component6_1.stl" scale="0.001 0.001 0.001"/>
    </geometry>
  </collision>
</link>

<link name="Component7_1">
  <inertial>
    <origin xyz="0.005170200721439387 0.002413878066284958 0.005899955125538814" rpy="0 0 0"/>
    <mass value="0.6310459992286263"/>
    <inertia ixx="0.000349" iyy="0.000311" izz="0.000335" ixy="-9e-06" iyz="1.7e-05" ixz="-1e-05"/>
  </inertial>
  <visual>
    <origin xyz="0.038086 -0.304001 -0.485222" rpy="0 0 0"/>
    <geometry>
      <mesh filename="package://Robotic_description/meshes/Component7_1.stl" scale="0.001 0.001 0.001"/>
    </geometry>
    <material name="silver"/>
  </visual>
  <collision>
    <origin xyz="0.038086 -0.304001 -0.485222" rpy="0 0 0"/>
    <geometry>
      <mesh filename="package://Robotic_description/meshes/Component7_1.stl" scale="0.001 0.001 0.001"/>
    </geometry>
  </collision>
</link>

<link name="Component8_Mirror__1">
  <inertial>
    <origin xyz="0.009343421801771373 0.02316394746506706 -0.022928258768890597" rpy="0 0 0"/>
    <mass value="0.17272823257156844"/>
    <inertia ixx="0.000115" iyy="2.2e-05" izz="0.000111" ixy="-2.2e-05" iyz="2.8e-05" ixz="6e-06"/>
  </inertial>
  <visual>
    <origin xyz="0.036895 -0.278425 -0.526488" rpy="0 0 0"/>
    <geometry>
      <mesh filename="package://Robotic_description/meshes/Component8_Mirror__1.stl" scale="0.001 0.001 0.001"/>
    </geometry>
    <material name="silver"/>
  </visual>
  <collision>
    <origin xyz="0.036895 -0.278425 -0.526488" rpy="0 0 0"/>
    <geometry>
      <mesh filename="package://Robotic_description/meshes/Component8_Mirror__1.stl" scale="0.001 0.001 0.001"/>
    </geometry>
  </collision>
</link>

<joint name="Revolute 2" type="continuous">
  <origin xyz="0.0 0.0 0.104" rpy="0 0 0"/>
  <parent link="base_link"/>
  <child link="Component2_1"/>
  <axis xyz="0.0 0.0 1.0"/>
</joint>

<joint name="Revolute 3" type="continuous">
  <origin xyz="-0.039991 0.144571 0.14" rpy="0 0 0"/>
  <parent link="Component2_1"/>
  <child link="Component3_1"/>
  <axis xyz="0.963805 0.266607 -0.0"/>
</joint>

<joint name="Revolute 4" type="continuous">
  <origin xyz="0.05347 -0.193299 0.286839" rpy="0 0 0"/>
  <parent link="Component3_1"/>
  <child link="Component4_1"/>
  <axis xyz="-0.963805 -0.266607 0.0"/>
</joint>

<joint name="Revolute 5" type="continuous">
  <origin xyz="-0.079282 0.185502 -0.049558" rpy="0 0 0"/>
  <parent link="Component4_1"/>
  <child link="Component5_1"/>
  <axis xyz="-0.23851 0.862233 -0.446842"/>
</joint>

<joint name="Revolute 6" type="continuous">
  <origin xyz="0.063131 0.153772 0.488872" rpy="0 0 0"/>
  <parent link="Component5_1"/>
  <child link="Component6_1"/>
  <axis xyz="0.769673 -0.112756 -0.628402"/>
</joint>

<joint name="Revolute 7" type="continuous">
  <origin xyz="-0.035414 0.013455 -0.484931" rpy="0 0 0"/>
  <parent link="Component6_1"/>
  <child link="Component7_1"/>
  <axis xyz="0.629954 0.294053 0.718812"/>
</joint>

<joint name="Revolute 9" type="continuous">
  <origin xyz="0.001191 -0.025576 0.041266" rpy="0 0 0"/>
  <parent link="Component7_1"/>
  <child link="Component8_Mirror__1"/>
  <axis xyz="0.772702 -0.330305 -0.542061"/>
</joint>

</robot>
